<?xml version="1.0" encoding="utf-8"?>
<!-- This URDF was automatically created by SolidWorks to URDF Exporter! Originally created by Stephen Brawner (brawner@gmail.com) 
     Commit Version: 1.6.0-1-g15f4949  Build Version: 1.6.7594.29634
     For more information, please see http://wiki.ros.org/sw_urdf_exporter -->
<robot
  name="linkerhand_X16_right.urdf">
  <link
    name="hand_base_link">
    <inertial>
      <origin
        xyz="-0.0032701 -0.00039398 0.050138"
        rpy="0 0 0" />
      <mass
        value="0.19126" />
      <inertia
        ixx="0.00029435"
        ixy="9.917E-07"
        ixz="1.3867E-07"
        iyy="0.00013626"
        iyz="-3.8443E-06"
        izz="0.00018783" />
    </inertial>
    <visual>
      <origin
        xyz="0 0 0"
        rpy="0 0 0" />
      <geometry>
        <mesh
          filename="meshes/hand_base_link.STL" />
      </geometry>
      <material
        name="">
        <color
          rgba="0.86667 0.86667 0.8902 1" />
      </material>
    </visual>
    <collision>
      <origin
        xyz="0 0 0"
        rpy="0 0 0" />
      <geometry>
        <mesh
          filename="meshes/hand_base_link.STL" />
      </geometry>
    </collision>
  </link>
  <link
    name="thumb_metacarpals_base1">
    <inertial>
      <origin
        xyz="0.0134149141149961 -0.00314146457560741 0.000236961025927893"
        rpy="0 0 0" />
      <mass
        value="0.0124712785430264" />
      <inertia
        ixx="2.17967773065547E-06"
        ixy="-1.124873136608E-07"
        ixz="-9.47830886794327E-09"
        iyy="1.16196412464816E-06"
        iyz="2.25484021737918E-08"
        izz="1.57436870805833E-06" />
    </inertial>
    <visual>
      <origin
        xyz="0 0 0"
        rpy="0 0 0" />
      <geometry>
        <mesh
          filename="meshes/thumb_metacarpals_base1.STL" />
      </geometry>
      <material
        name="">
        <color
          rgba="0.866666666666667 0.866666666666667 0.890196078431372 1" />
      </material>
    </visual>
    <collision>
      <origin
        xyz="0 0 0"
        rpy="0 0 0" />
      <geometry>
        <mesh
          filename="meshes/thumb_metacarpals_base1.STL" />
      </geometry>
    </collision>
  </link>
  <joint
    name="thumb_cmc_roll"
    type="revolute">
    <origin
      xyz="-0.00068832 0.0227 0.0241"
      rpy="0 0 0" />
    <parent
      link="hand_base_link" />
    <child
      link="thumb_metacarpals_base1" />
    <axis
      xyz="1 0 0" />
    <limit
      lower="0"
      upper="0.489"
      effort="0"
      velocity="0" />
  </joint>
  <link
    name="thumb_metacarpals_base2">
    <inertial>
      <origin
        xyz="0.00805043118604656 0.00884632333664083 0.00165149279214109"
        rpy="0 0 0" />
      <mass
        value="0.00506529344098014" />
      <inertia
        ixx="4.26027463795075E-07"
        ixy="-2.00364210221145E-07"
        ixz="-2.38147412527679E-08"
        iyy="3.92190616749035E-07"
        iyz="-6.80837938933958E-08"
        izz="4.43759231454847E-07" />
    </inertial>
    <visual>
      <origin
        xyz="0 0 0"
        rpy="0 0 0" />
      <geometry>
        <mesh
          filename="meshes/thumb_metacarpals_base2.STL" />
      </geometry>
      <material
        name="">
        <color
          rgba="0.898039215686275 0.917647058823529 0.929411764705882 1" />
      </material>
    </visual>
    <collision>
      <origin
        xyz="0 0 0"
        rpy="0 0 0" />
      <geometry>
        <mesh
          filename="meshes/thumb_metacarpals_base2.STL" />
      </geometry>
    </collision>
  </link>
  <joint
    name="thumb_cmc_yaw"
    type="revolute">
    <origin
      xyz="0.021071 0.0032693 -0.00045946"
      rpy="0 0 0" />
    <parent
      link="thumb_metacarpals_base1" />
    <child
      link="thumb_metacarpals_base2" />
    <axis
      xyz="0 -0.13917 -0.99027" />
    <limit
      lower="0"
      upper="1.309"
      effort="0"
      velocity="0" />
  </joint>
  <link
    name="thumb_metacarpals">
    <inertial>
      <origin
        xyz="0.0134575289023575 0.0158479099940706 0.0176459520563751"
        rpy="0 0 0" />
      <mass
        value="0.0603583651520557" />
      <inertia
        ixx="1.77961199123504E-05"
        ixy="-6.55218856957268E-06"
        ixz="-3.61166112314609E-06"
        iyy="1.64177405926455E-05"
        iyz="-4.81885596450216E-06"
        izz="1.52427517706849E-05" />
    </inertial>
    <visual>
      <origin
        xyz="0 0 0"
        rpy="0 0 0" />
      <geometry>
        <mesh
          filename="meshes/thumb_metacarpals.STL" />
      </geometry>
      <material
        name="">
        <color
          rgba="0.866666666666667 0.866666666666667 0.890196078431372 1" />
      </material>
    </visual>
    <collision>
      <origin
        xyz="0 0 0"
        rpy="0 0 0" />
      <geometry>
        <mesh
          filename="meshes/thumb_metacarpals.STL" />
      </geometry>
    </collision>
  </link>
  <joint
    name="thumb_cmc_pitch"
    type="revolute">
    <origin
      xyz="0.019046 0.019815 0.0041436"
      rpy="0 0 0" />
    <parent
      link="thumb_metacarpals_base2" />
    <child
      link="thumb_metacarpals" />
    <axis
      xyz="-0.70711 0.70023 -0.09841" />
    <limit
      lower="0"
      upper="0.8377"
      effort="0"
      velocity="0" />
  </joint>
  <link
    name="thumb_proximal">
    <inertial>
      <origin
        xyz="0.0088055016261689 0.00912584408154034 0.00603790594911241"
        rpy="0 0 0" />
      <mass
        value="0.0150720015495994" />
      <inertia
        ixx="1.3893239554546E-06"
        ixy="-3.25684023949997E-07"
        ixz="-2.05726562819854E-07"
        iyy="1.32509489079776E-06"
        iyz="-3.07318894719417E-07"
        izz="9.05409424684871E-07" />
    </inertial>
    <visual>
      <origin
        xyz="0 0 0"
        rpy="0 0 0" />
      <geometry>
        <mesh
          filename="meshes/thumb_proximal.STL" />
      </geometry>
      <material
        name="">
        <color
          rgba="0.866666666666667 0.866666666666667 0.890196078431372 1" />
      </material>
    </visual>
    <collision>
      <origin
        xyz="0 0 0"
        rpy="0 0 0" />
      <geometry>
        <mesh
          filename="meshes/thumb_proximal.STL" />
      </geometry>
    </collision>
  </link>
  <joint
    name="thumb_mcp"
    type="revolute">
    <origin
      xyz="0.027783 0.033111 0.035966"
      rpy="0 0 0" />
    <parent
      link="thumb_metacarpals" />
    <child
      link="thumb_proximal" />
    <axis
      xyz="0.70711 -0.70023 0.09841" />
    <limit
      lower="0"
      upper="1.298"
      effort="0"
      velocity="0" />
    <!-- <mimic
      joint="thumb_ip"
      multiplier="1.09"
      offset="0" /> -->
  </joint>
  <link
    name="thumb_distal">
    <inertial>
      <origin
        xyz="0.00609115305520601 0.00690201813049127 0.00653360880975751"
        rpy="0 0 0" />
      <mass
        value="0.0180991265717759" />
      <inertia
        ixx="1.02177249807416E-06"
        ixy="-3.12347597963975E-07"
        ixz="-1.25867848433246E-07"
        iyy="9.87790373302599E-07"
        iyz="-1.11671217078542E-07"
        izz="1.44700987728898E-06" />
    </inertial>
    <visual>
      <origin
        xyz="0 0 0"
        rpy="0 0 0" />
      <geometry>
        <mesh
          filename="meshes/thumb_distal.STL" />
      </geometry>
      <material
        name="">
        <color
          rgba="0.866666666666667 0.866666666666667 0.890196078431372 1" />
      </material>
    </visual>
    <collision>
      <origin
        xyz="0 0 0"
        rpy="0 0 0" />
      <geometry>
        <mesh
          filename="meshes/thumb_distal.STL" />
      </geometry>
    </collision>
  </link>
  <joint
    name="thumb_ip"
    type="revolute">
    <origin
      xyz="0.019768 0.022404 0.017375"
      rpy="0 0 0" />
    <parent
      link="thumb_proximal" />
    <child
      link="thumb_distal" />
    <axis
      xyz="0.70711 -0.70023 0.09841" />
    <limit
      lower="0"
      upper="1.413"
      effort="0"
      velocity="0" />
    <mimic
      joint="thumb_mcp"
      multiplier="1.09"
      offset="0" />
  </joint>
  <link
    name="index_metacarpals">
    <inertial>
      <origin
        xyz="0.00800315592241141 7.08671565874397E-10 0.00243768809275643"
        rpy="0 0 0" />
      <mass
        value="0.0069674641924626" />
      <inertia
        ixx="2.79763563546334E-07"
        ixy="9.18887208384515E-14"
        ixz="-2.63807738530808E-08"
        iyy="1.64332169287868E-07"
        iyz="1.87282512364522E-13"
        izz="2.88425815686695E-07" />
    </inertial>
    <visual>
      <origin
        xyz="0 0 0"
        rpy="0 0 0" />
      <geometry>
        <mesh
          filename="meshes/index_metacarpals.STL" />
      </geometry>
      <material
        name="">
        <color
          rgba="0.647058823529412 0.619607843137255 0.588235294117647 1" />
      </material>
    </visual>
    <collision>
      <origin
        xyz="0 0 0"
        rpy="0 0 0" />
      <geometry>
        <mesh
          filename="meshes/index_metacarpals.STL" />
      </geometry>
    </collision>
  </link>
  <joint
    name="index_mcp_roll"
    type="revolute">
    <origin
      xyz="-0.012538 0.036 0.1048"
      rpy="0 0 0" />
    <parent
      link="hand_base_link" />
    <child
      link="index_metacarpals" />
    <axis
      xyz="-1 0 0" />
    <limit
      lower="-0.18"
      upper="0.18"
      effort="0"
      velocity="0" />
  </joint>
  <link
    name="index_proximal">
    <inertial>
      <origin
        xyz="-0.00110781163691715 1.35676546516098E-05 0.0198634344199539"
        rpy="0 0 0" />
      <mass
        value="0.0120280208732201" />
      <inertia
        ixx="1.46103143499729E-06"
        ixy="3.66961357213296E-10"
        ixz="6.35397675144472E-08"
        iyy="1.53409812879568E-06"
        iyz="6.6364794892568E-11"
        izz="3.46231626289234E-07" />
    </inertial>
    <visual>
      <origin
        xyz="0 0 0"
        rpy="0 0 0" />
      <geometry>
        <mesh
          filename="meshes/index_proximal.STL" />
      </geometry>
      <material
        name="">
        <color
          rgba="0.866666666666667 0.866666666666667 0.890196078431372 1" />
      </material>
    </visual>
    <collision>
      <origin
        xyz="0 0 0"
        rpy="0 0 0" />
      <geometry>
        <mesh
          filename="meshes/index_proximal.STL" />
      </geometry>
    </collision>
  </link>
  <joint
    name="index_mcp_pitch"
    type="revolute">
    <origin
      xyz="0.0126198026192479 0 0"
      rpy="0 0 0" />
    <parent
      link="index_metacarpals" />
    <child
      link="index_proximal" />
    <axis
      xyz="0 1 0" />
    <limit
      lower="0"
      upper="1.396"
      effort="0"
      velocity="0" />
  </joint>
  <link
    name="index_middle">
    <inertial>
      <origin
        xyz="0.00144995351926267 -2.55936957252456E-08 0.0145841621274674"
        rpy="0 0 0" />
      <mass
        value="0.00579467340423502" />
      <inertia
        ixx="5.16430134727309E-07"
        ixy="-3.57694136908858E-13"
        ixz="-5.16490243274308E-08"
        iyy="4.38018614758759E-07"
        iyz="6.16718796704541E-13"
        izz="3.28703138818955E-07" />
    </inertial>
    <visual>
      <origin
        xyz="0 0 0"
        rpy="0 0 0" />
      <geometry>
        <mesh
          filename="meshes/index_middle.STL" />
      </geometry>
      <material
        name="">
        <color
          rgba="0.866666666666667 0.866666666666667 0.890196078431372 1" />
      </material>
    </visual>
    <collision>
      <origin
        xyz="0 0 0"
        rpy="0 0 0" />
      <geometry>
        <mesh
          filename="meshes/index_middle.STL" />
      </geometry>
    </collision>
  </link>
  <joint
    name="index_pip"
    type="revolute">
    <origin
      xyz="-0.0039371 0 0.03983"
      rpy="0 0 0" />
    <parent
      link="index_proximal" />
    <child
      link="index_middle" />
    <axis
      xyz="0 1 0" />
    <limit
      lower="0"
      upper="1.571"
      effort="0"
      velocity="0" />
    <!-- <mimic
      joint="index_dip"
      multiplier="0.84"
      offset="0" /> -->
  </joint>
  <link
    name="index_distal">
    <inertial>
      <origin
        xyz="-0.00658736294329401 -6.21153760196197E-06 0.00719584531070251"
        rpy="0 0 0" />
      <mass
        value="0.0111896165115351" />
      <inertia
        ixx="9.25371538349445E-07"
        ixy="8.08371952309705E-11"
        ixz="1.44269971506002E-07"
        iyy="9.68362345228068E-07"
        iyz="-5.35872701431461E-10"
        izz="3.78279514208212E-07" />
    </inertial>
    <visual>
      <origin
        xyz="0 0 0"
        rpy="0 0 0" />
      <geometry>
        <mesh
          filename="meshes/index_distal.STL" />
      </geometry>
      <material
        name="">
        <color
          rgba="0.866666666666667 0.866666666666667 0.890196078431372 1" />
      </material>
    </visual>
    <collision>
      <origin
        xyz="0 0 0"
        rpy="0 0 0" />
      <geometry>
        <mesh
          filename="meshes/index_distal.STL" />
      </geometry>
    </collision>
  </link>
  <joint
    name="index_dip"
    type="revolute">
    <origin
      xyz="0.0057839 0 0.026493"
      rpy="0 0 0" />
    <parent
      link="index_middle" />
    <child
      link="index_distal" />
    <axis
      xyz="0 1 0" />
    <limit
      lower="0"
      upper="1.326"
      effort="0"
      velocity="0" />
    <mimic
      joint="index_pip"
      multiplier="0.84"
      offset="0" />
  </joint>
  <link
    name="middle_metacarpals">
    <inertial>
      <origin
        xyz="0.0080031559224114 7.09556908021214E-10 0.00243768809275643"
        rpy="0 0 0" />
      <mass
        value="0.00696746419246259" />
      <inertia
        ixx="2.79763563546334E-07"
        ixy="9.1888720785087E-14"
        ixz="-2.63807738530808E-08"
        iyy="1.64332169287868E-07"
        iyz="1.87282512553076E-13"
        izz="2.88425815686695E-07" />
    </inertial>
    <visual>
      <origin
        xyz="0 0 0"
        rpy="0 0 0" />
      <geometry>
        <mesh
          filename="meshes/middle_metacarpals.STL" />
      </geometry>
      <material
        name="">
        <color
          rgba="0.647058823529412 0.619607843137255 0.588235294117647 1" />
      </material>
    </visual>
    <collision>
      <origin
        xyz="0 0 0"
        rpy="0 0 0" />
      <geometry>
        <mesh
          filename="meshes/middle_metacarpals.STL" />
      </geometry>
    </collision>
  </link>
  <joint
    name="middle_mcp_roll"
    type="revolute">
    <origin
      xyz="-0.012538 0.012 0.1048"
      rpy="0 0 0" />
    <parent
      link="hand_base_link" />
    <child
      link="middle_metacarpals" />
    <axis
      xyz="-1 0 0" />
    <limit
      lower="-0.18"
      upper="0.18"
      effort="0"
      velocity="0" />
  </joint>
  <link
    name="middle_proximal">
    <inertial>
      <origin
        xyz="-0.0011078116369171 1.35676546516462E-05 0.0198634344199539"
        rpy="0 0 0" />
      <mass
        value="0.01202802087322" />
      <inertia
        ixx="1.46103143499732E-06"
        ixy="3.66961357216841E-10"
        ixz="6.35397675144443E-08"
        iyy="1.53409812879568E-06"
        iyz="6.63647948882004E-11"
        izz="3.4623162628927E-07" />
    </inertial>
    <visual>
      <origin
        xyz="0 0 0"
        rpy="0 0 0" />
      <geometry>
        <mesh
          filename="meshes/middle_proximal.STL" />
      </geometry>
      <material
        name="">
        <color
          rgba="0.866666666666667 0.866666666666667 0.890196078431372 1" />
      </material>
    </visual>
    <collision>
      <origin
        xyz="0 0 0"
        rpy="0 0 0" />
      <geometry>
        <mesh
          filename="meshes/middle_proximal.STL" />
      </geometry>
    </collision>
  </link>
  <joint
    name="middle_mcp_pitch"
    type="revolute">
    <origin
      xyz="0.0126198026192479 0 0"
      rpy="0 0 0" />
    <parent
      link="middle_metacarpals" />
    <child
      link="middle_proximal" />
    <axis
      xyz="0 1 0" />
    <limit
      lower="0"
      upper="1.396"
      effort="0"
      velocity="0" />
  </joint>
  <link
    name="middle_middle">
    <inertial>
      <origin
        xyz="0.00144995351926266 -2.55936957287151E-08 0.0145841621274674"
        rpy="0 0 0" />
      <mass
        value="0.00579467340423501" />
      <inertia
        ixx="5.16430134727308E-07"
        ixy="-3.57694136616036E-13"
        ixz="-5.16490243274302E-08"
        iyy="4.3801861475876E-07"
        iyz="6.16718797019667E-13"
        izz="3.28703138818957E-07" />
    </inertial>
    <visual>
      <origin
        xyz="0 0 0"
        rpy="0 0 0" />
      <geometry>
        <mesh
          filename="meshes/middle_middle.STL" />
      </geometry>
      <material
        name="">
        <color
          rgba="0.866666666666667 0.866666666666667 0.890196078431372 1" />
      </material>
    </visual>
    <collision>
      <origin
        xyz="0 0 0"
        rpy="0 0 0" />
      <geometry>
        <mesh
          filename="meshes/middle_middle.STL" />
      </geometry>
    </collision>
  </link>
  <joint
    name="middle_pip"
    type="revolute">
    <origin
      xyz="-0.0039371 0 0.03983"
      rpy="0 0 0" />
    <parent
      link="middle_proximal" />
    <child
      link="middle_middle" />
    <axis
      xyz="0 1 0" />
    <limit
      lower="0"
      upper="1.571"
      effort="0"
      velocity="0" />
    <!-- <mimic
      joint="middle_dip"
      multiplier="0.84"
      offset="0" /> -->
  </joint>
  <link
    name="middle_distal">
    <inertial>
      <origin
        xyz="-0.00658736354875118 -6.21148949159211E-06 0.00719584663647685"
        rpy="0 0 0" />
      <mass
        value="0.0111896176823709" />
      <inertia
        ixx="9.25371686065313E-07"
        ixy="8.08501082466414E-11"
        ixz="1.4427006038686E-07"
        iyy="9.68362531803104E-07"
        iyz="-5.35883133574264E-10"
        izz="3.78279561675847E-07" />
    </inertial>
    <visual>
      <origin
        xyz="0 0 0"
        rpy="0 0 0" />
      <geometry>
        <mesh
          filename="meshes/middle_distal.STL" />
      </geometry>
      <material
        name="">
        <color
          rgba="0.866666666666667 0.866666666666667 0.890196078431372 1" />
      </material>
    </visual>
    <collision>
      <origin
        xyz="0 0 0"
        rpy="0 0 0" />
      <geometry>
        <mesh
          filename="meshes/middle_distal.STL" />
      </geometry>
    </collision>
  </link>
  <joint
    name="middle_dip"
    type="revolute">
    <origin
      xyz="0.0057839 0 0.026493"
      rpy="0 0 0" />
    <parent
      link="middle_middle" />
    <child
      link="middle_distal" />
    <axis
      xyz="0 1 0" />
    <limit
      lower="0"
      upper="1.326"
      effort="0"
      velocity="0" />
    <mimic
      joint="middle_pip"
      multiplier="0.84"
      offset="0" />
  </joint>
  <link
    name="ring_metacarpals">
    <inertial>
      <origin
        xyz="0.0080031559224114 7.09556911490661E-10 0.00243768809275643"
        rpy="0 0 0" />
      <mass
        value="0.0069674641924626" />
      <inertia
        ixx="2.79763563546334E-07"
        ixy="9.18887208201558E-14"
        ixz="-2.63807738530808E-08"
        iyy="1.64332169287868E-07"
        iyz="1.87282512552189E-13"
        izz="2.88425815686695E-07" />
    </inertial>
    <visual>
      <origin
        xyz="0 0 0"
        rpy="0 0 0" />
      <geometry>
        <mesh
          filename="meshes/ring_metacarpals.STL" />
      </geometry>
      <material
        name="">
        <color
          rgba="0.647058823529412 0.619607843137255 0.588235294117647 1" />
      </material>
    </visual>
    <collision>
      <origin
        xyz="0 0 0"
        rpy="0 0 0" />
      <geometry>
        <mesh
          filename="meshes/ring_metacarpals.STL" />
      </geometry>
    </collision>
  </link>
  <joint
    name="ring_mcp_roll"
    type="revolute">
    <origin
      xyz="-0.012538 -0.012 0.1048"
      rpy="0 0 0" />
    <parent
      link="hand_base_link" />
    <child
      link="ring_metacarpals" />
    <axis
      xyz="-1 0 0" />
    <limit
      lower="-0.18"
      upper="0.18"
      effort="0"
      velocity="0" />
  </joint>
  <link
    name="ring_proximal">
    <inertial>
      <origin
        xyz="-0.00110781163691709 1.35676546516496E-05 0.0198634344199539"
        rpy="0 0 0" />
      <mass
        value="0.01202802087322" />
      <inertia
        ixx="1.46103143499725E-06"
        ixy="3.66961357216082E-10"
        ixz="6.35397675144444E-08"
        iyy="1.53409812879568E-06"
        iyz="6.63647948900136E-11"
        izz="3.46231626289199E-07" />
    </inertial>
    <visual>
      <origin
        xyz="0 0 0"
        rpy="0 0 0" />
      <geometry>
        <mesh
          filename="meshes/ring_proximal.STL" />
      </geometry>
      <material
        name="">
        <color
          rgba="0.866666666666667 0.866666666666667 0.890196078431372 1" />
      </material>
    </visual>
    <collision>
      <origin
        xyz="0 0 0"
        rpy="0 0 0" />
      <geometry>
        <mesh
          filename="meshes/ring_proximal.STL" />
      </geometry>
    </collision>
  </link>
  <joint
    name="ring_mcp_pitch"
    type="revolute">
    <origin
      xyz="0.0126198026192479 0 0"
      rpy="0 0 0" />
    <parent
      link="ring_metacarpals" />
    <child
      link="ring_proximal" />
    <axis
      xyz="0 1 0" />
    <limit
      lower="0"
      upper="1.396"
      effort="0"
      velocity="0" />
  </joint>
  <link
    name="ring_middle">
    <inertial>
      <origin
        xyz="0.00144995351926267 -2.55936957287151E-08 0.0145841621274674"
        rpy="0 0 0" />
      <mass
        value="0.00579467340423501" />
      <inertia
        ixx="5.16430134727307E-07"
        ixy="-3.57694136897408E-13"
        ixz="-5.16490243274303E-08"
        iyy="4.38018614758758E-07"
        iyz="6.16718796522935E-13"
        izz="3.28703138818955E-07" />
    </inertial>
    <visual>
      <origin
        xyz="0 0 0"
        rpy="0 0 0" />
      <geometry>
        <mesh
          filename="meshes/ring_middle.STL" />
      </geometry>
      <material
        name="">
        <color
          rgba="0.866666666666667 0.866666666666667 0.890196078431372 1" />
      </material>
    </visual>
    <collision>
      <origin
        xyz="0 0 0"
        rpy="0 0 0" />
      <geometry>
        <mesh
          filename="meshes/ring_middle.STL" />
      </geometry>
    </collision>
  </link>
  <joint
    name="ring_pip"
    type="revolute">
    <origin
      xyz="-0.0039371 0 0.03983"
      rpy="0 0 0" />
    <parent
      link="ring_proximal" />
    <child
      link="ring_middle" />
    <axis
      xyz="0 1 0" />
    <limit
      lower="0"
      upper="1.571"
      effort="0"
      velocity="0" />
    <!-- <mimic
      joint="ring_dip"
      multiplier="0.84"
      offset="0" /> -->
  </joint>
  <link
    name="ring_distal">
    <inertial>
      <origin
        xyz="-0.0065873637633613 -6.21123599489973E-06 0.00719584718036041"
        rpy="0 0 0" />
      <mass
        value="0.0111896181478205" />
      <inertia
        ixx="9.25371802908145E-07"
        ixy="8.08587854920271E-11"
        ixz="1.44270104853326E-07"
        iyy="9.68362656214778E-07"
        iyz="-5.35919195581449E-10"
        izz="3.78279576434363E-07" />
    </inertial>
    <visual>
      <origin
        xyz="0 0 0"
        rpy="0 0 0" />
      <geometry>
        <mesh
          filename="meshes/ring_distal.STL" />
      </geometry>
      <material
        name="">
        <color
          rgba="0.866666666666667 0.866666666666667 0.890196078431372 1" />
      </material>
    </visual>
    <collision>
      <origin
        xyz="0 0 0"
        rpy="0 0 0" />
      <geometry>
        <mesh
          filename="meshes/ring_distal.STL" />
      </geometry>
    </collision>
  </link>
  <joint
    name="ring_dip"
    type="revolute">
    <origin
      xyz="0.0057839 0 0.026493"
      rpy="0 0 0" />
    <parent
      link="ring_middle" />
    <child
      link="ring_distal" />
    <axis
      xyz="0 1 0" />
    <limit
      lower="0"
      upper="1.326"
      effort="0"
      velocity="0" />
    <mimic
      joint="ring_pip"
      multiplier="0.84"
      offset="0" />
  </joint>
  <link
    name="pinky_metacarpals">
    <inertial>
      <origin
        xyz="0 0 0"
        rpy="0 0 0" />
      <mass
        value="0" />
      <inertia
        ixx="0"
        ixy="0"
        ixz="0"
        iyy="0"
        iyz="0"
        izz="0" />
    </inertial>
    <visual>
      <origin
        xyz="0 0 0"
        rpy="0 0 0" />
      <geometry>
        <mesh
          filename="meshes/pinky_metacarpals.STL" />
      </geometry>
      <material
        name="">
        <color
          rgba="1 1 1 1" />
      </material>
    </visual>
    <collision>
      <origin
        xyz="0 0 0"
        rpy="0 0 0" />
      <geometry>
        <mesh
          filename="meshes/pinky_metacarpals.STL" />
      </geometry>
    </collision>
  </link>
  <joint
    name="pinky_mcp_roll"
    type="revolute">
    <origin
      xyz="-0.0125383237132332 -0.0360000000008864 0.104800005371604"
      rpy="0 0 0" />
    <parent
      link="hand_base_link" />
    <child
      link="pinky_metacarpals" />
    <axis
      xyz="-1 0 0" />
    <limit
      lower="-0.18"
      upper="0.18"
      effort="0"
      velocity="0" />
  </joint>
  <link
    name="pinky_proximal">
    <inertial>
      <origin
        xyz="-0.0011078116369171 1.35676546516375E-05 0.0198634344199539"
        rpy="0 0 0" />
      <mass
        value="0.0120280208732199" />
      <inertia
        ixx="1.46103143499727E-06"
        ixy="3.66961357217407E-10"
        ixz="6.3539767514444E-08"
        iyy="1.53409812879568E-06"
        iyz="6.63647948885181E-11"
        izz="3.46231626289219E-07" />
    </inertial>
    <visual>
      <origin
        xyz="0 0 0"
        rpy="0 0 0" />
      <geometry>
        <mesh
          filename="meshes/pinky_proximal.STL" />
      </geometry>
      <material
        name="">
        <color
          rgba="0.866666666666667 0.866666666666667 0.890196078431372 1" />
      </material>
    </visual>
    <collision>
      <origin
        xyz="0 0 0"
        rpy="0 0 0" />
      <geometry>
        <mesh
          filename="meshes/pinky_proximal.STL" />
      </geometry>
    </collision>
  </link>
  <joint
    name="pinky_mcp_pitch"
    type="revolute">
    <origin
      xyz="0.0126198026192479 0 0"
      rpy="0 0 0" />
    <parent
      link="pinky_metacarpals" />
    <child
      link="pinky_proximal" />
    <axis
      xyz="0 1 0" />
    <limit
      lower="0"
      upper="1.396"
      effort="0"
      velocity="0" />
  </joint>
  <link
    name="pinky_middle">
    <inertial>
      <origin
        xyz="0.00144995351926266 -2.55936957113678E-08 0.0145841621274674"
        rpy="0 0 0" />
      <mass
        value="0.00579467340423503" />
      <inertia
        ixx="5.16430134727309E-07"
        ixy="-3.57694136832206E-13"
        ixz="-5.16490243274304E-08"
        iyy="4.3801861475876E-07"
        iyz="6.16718796746389E-13"
        izz="3.28703138818957E-07" />
    </inertial>
    <visual>
      <origin
        xyz="0 0 0"
        rpy="0 0 0" />
      <geometry>
        <mesh
          filename="meshes/pinky_middle.STL" />
      </geometry>
      <material
        name="">
        <color
          rgba="0.866666666666667 0.866666666666667 0.890196078431372 1" />
      </material>
    </visual>
    <collision>
      <origin
        xyz="0 0 0"
        rpy="0 0 0" />
      <geometry>
        <mesh
          filename="meshes/pinky_middle.STL" />
      </geometry>
    </collision>
  </link>
  <joint
    name="pinky_pip"
    type="revolute">
    <origin
      xyz="-0.0039371 0 0.03983"
      rpy="0 0 0" />
    <parent
      link="pinky_proximal" />
    <child
      link="pinky_middle" />
    <axis
      xyz="0 1 0" />
    <limit
      lower="0"
      upper="1.571"
      effort="0"
      velocity="0" />
    <!-- <mimic
      joint="pinky_dip"
      multiplier="0.84"
      offset="0" /> -->
  </joint>
  <link
    name="pinky_distal">
    <inertial>
      <origin
        xyz="-0.00658736312101682 -6.21108476379223E-06 0.00719584585373223"
        rpy="0 0 0" />
      <mass
        value="0.011189616983666" />
      <inertia
        ixx="9.25371626743596E-07"
        ixy="8.08706417013186E-11"
        ixz="1.44269999267233E-07"
        iyy="9.68362436541112E-07"
        iyz="-5.35942500746081E-10"
        izz="3.78279526412102E-07" />
    </inertial>
    <visual>
      <origin
        xyz="0 0 0"
        rpy="0 0 0" />
      <geometry>
        <mesh
          filename="meshes/pinky_distal.STL" />
      </geometry>
      <material
        name="">
        <color
          rgba="0.866666666666667 0.866666666666667 0.890196078431372 1" />
      </material>
    </visual>
    <collision>
      <origin
        xyz="0 0 0"
        rpy="0 0 0" />
      <geometry>
        <mesh
          filename="meshes/pinky_distal.STL" />
      </geometry>
    </collision>
  </link>
  <joint
    name="pinky_dip"
    type="revolute">
    <origin
      xyz="0.0057839 0 0.026493"
      rpy="0 0 0" />
    <parent
      link="pinky_middle" />
    <child
      link="pinky_distal" />
    <axis
      xyz="0 1 0" />
    <limit
      lower="0"
      upper="1.326"
      effort="0"
      velocity="0" />
    <mimic
      joint="pinky_pip"
      multiplier="0.84"
      offset="0" />
  </joint>
</robot>